<?xml version="1.0" encoding="utf-8"?>
<!-- This URDF was automatically created by SolidWorks to URDF Exporter! Originally created by Stephen Brawner (brawner@gmail.com) 
     Commit Version: 1.6.0-4-g7f85cfe  Build Version: 1.6.7995.38578
     For more information, please see http://wiki.ros.org/sw_urdf_exporter -->
<robot
  name="ensamblaje">
  <link
    name="base_link">
    <inertial>
      <origin
        xyz="-0.0031922 5.2125E-10 0.042401"
        rpy="0 0 0" />
      <mass
        value="0.38379" />
      <inertia
        ixx="0.0003549"
        ixy="1.7886E-12"
        ixz="-3.9495E-05"
        iyy="0.00041474"
        iyz="6.195E-13"
        izz="0.00033584" />
    </inertial>
    <visual>
      <origin
        xyz="0 0 0"
        rpy="0 0 0" />
      <geometry>
        <mesh
          filename="package://ensamblaje/meshes/base_link.STL" />
      </geometry>
      <material
        name="">
        <color
          rgba="0.79216 0.81961 0.93333 1" />
      </material>
    </visual>
    <collision>
      <origin
        xyz="0 0 0"
        rpy="0 0 0" />
      <geometry>
        <mesh
          filename="package://ensamblaje/meshes/base_link.STL" />
      </geometry>
    </collision>
  </link>
  <link
    name="brazo_link">
    <inertial>
      <origin
        xyz="0.11104 -2.0637E-05 0.010869"
        rpy="0 0 0" />
      <mass
        value="0.44515" />
      <inertia
        ixx="0.00026796"
        ixy="7.3938E-08"
        ixz="1.1718E-05"
        iyy="0.0025749"
        iyz="-4.1064E-10"
        izz="0.0028234" />
    </inertial>
    <visual>
      <origin
        xyz="0 0 0"
        rpy="0 0 0" />
      <geometry>
        <mesh
          filename="package://ensamblaje/meshes/brazo_link.STL" />
      </geometry>
      <material
        name="">
        <color
          rgba="0.79216 0.81961 0.93333 1" />
      </material>
    </visual>
    <collision>
      <origin
        xyz="0 0 0"
        rpy="0 0 0" />
      <geometry>
        <mesh
          filename="package://ensamblaje/meshes/brazo_link.STL" />
      </geometry>
    </collision>
  </link>
  <joint
    name="brazo_joint"
    type="revolute">
    <origin
      xyz="0 0 0.1077"
      rpy="0 0 0" />
    <parent
      link="base_link" />
    <child
      link="brazo_link" />
    <axis
      xyz="0 0 1" />
    <limit
      lower="-1.5707"
      upper="1.5707"
      effort="0"
      velocity="1" />
  </joint>
  <link
    name="antebrazo_link">
    <inertial>
      <origin
        xyz="0.096735 3.7289E-06 0.0074634"
        rpy="0 0 0" />
      <mass
        value="0.37688" />
      <inertia
        ixx="0.00025699"
        ixy="-1.1824E-08"
        ixz="-9.8018E-07"
        iyy="0.0025405"
        iyz="4.5851E-12"
        izz="0.0027833" />
    </inertial>
    <visual>
      <origin
        xyz="0 0 0"
        rpy="0 0 0" />
      <geometry>
        <mesh
          filename="package://ensamblaje/meshes/antebrazo_link.STL" />
      </geometry>
      <material
        name="">
        <color
          rgba="0.79216 0.81961 0.93333 1" />
      </material>
    </visual>
    <collision>
      <origin
        xyz="0 0 0"
        rpy="0 0 0" />
      <geometry>
        <mesh
          filename="package://ensamblaje/meshes/antebrazo_link.STL" />
      </geometry>
    </collision>
  </link>
  <joint
    name="antebrazo_joint"
    type="revolute">
    <origin
      xyz="0.21502 0 -0.02"
      rpy="0 0 0" />
    <parent
      link="brazo_link" />
    <child
      link="antebrazo_link" />
    <axis
      xyz="0 0 1" />
    <limit
      lower="-1.5707"
      upper="1.5707"
      effort="0"
      velocity="1" />
  </joint>
  <link
    name="efector_link">
    <inertial>
      <origin
        xyz="0 -4.0612E-06 -0.037471"
        rpy="0 0 0" />
      <mass
        value="0.025072" />
      <inertia
        ixx="1.3992E-05"
        ixy="-2.1453E-24"
        ixz="2.8726E-22"
        iyy="1.3999E-05"
        iyz="3.8969E-24"
        izz="1.2444E-06" />
    </inertial>
    <visual>
      <origin
        xyz="0 0 0"
        rpy="0 0 0" />
      <geometry>
        <mesh
          filename="package://ensamblaje/meshes/efector_link.STL" />
      </geometry>
      <material
        name="">
        <color
          rgba="0.79216 0.81961 0.93333 1" />
      </material>
    </visual>
    <collision>
      <origin
        xyz="0 0 0"
        rpy="0 0 0" />
      <geometry>
        <mesh
          filename="package://ensamblaje/meshes/efector_link.STL" />
      </geometry>
    </collision>
  </link>
  <joint
    name="efector_joint"
    type="prismatic">
    <origin
      xyz="0.215 0 -0.01"
      rpy="3.1416 0 0" />
    <parent
      link="antebrazo_link" />
    <child
      link="efector_link" />
    <axis
      xyz="0 0 1" />
    <limit
      lower="0"
      upper="0.05"
      effort="0"
      velocity="1" />
  </joint>
</robot>